Workbook

Sheet MAIN CATALOG NEW
A1: Shelf # | B1: # on Shelf | C1: Title of Item | D1: Author Name | E1: Checkout Date | F1: Due Date | G1: Checkout Form Here!
A2: FIRST SHELF: DVDS | B2: 1 | C2: ='Shelf 1 - DVDs'!B2 -> A Single Man
B3: =B2+1 -> 2 | C3: ='Shelf 1 - DVDs'!B3 -> Becoming Chaz
B4: =B3+1 -> 3 | C4: ='Shelf 1 - DVDs'!B4 -> black./womyn: conversations with lesbians of African descent.
B5: =B4+1 -> 4 | C5: ='Shelf 1 - DVDs'!B5 -> Bridegroom
B6: =B5+1 -> 5 | C6: ='Shelf 1 - DVDs'!B6 -> Chely Wright: Wish Me Away
B7: =B6+1 -> 6 | C7: ='Shelf 1 - DVDs'!B7 -> Circumstance
B8: =B7+1 -> 7 | C8: Clown
B9: =B8+1 -> 8 | C9: Everybody's Fine
B10: =B9+1 -> 9 | C10: for the Bible tells me so
B11: =B10+1 -> 10 | C11: Freedom to Marry, The
B12: =B11+1 -> 11 | C12: happy
B13: =B12+1 -> 12 | C13: Happy Together
B14: =B13+1 -> 13 | C14: Heartbeats
B15: =B14+1 -> 14 | C15: Heavenly Creatures
B16: =B15+1 -> 15 | C16: high art
B17: =B16+1 -> 16 | C17: Human Doc: Old Pink
B18: =B17+1 -> 17 | C18: I Love You Phillip Morris
B19: =B18+1 -> 18 | C19: if these walls could talk 2
... B38: =B37+1 -> 37 | C38: Y Tu Mama Tambien
B39: =B38+1 -> 38
B40: =B39+1 -> 39 | C40: ='Shelf 1 - DVDs'!B40
B41: =B40+1 -> 40 | C41: ='Shelf 1 - DVDs'!B41
A42: SECOND SHELF: SMALL BOOKS | B42: 1 | C42: ='Shelf 2 - Small Books'!B2 -> A Quick & Easy Guide to Consent | D42: ='Shelf 2 - Small Books'!C2 -> Rotman, Isabella & Howard, Luke B.
B43: 2 | C43: ='Shelf 2 - Small Books'!B3 -> A Quick & Easy Guide to Sex & Disability | D43: ='Shelf 2 - Small Books'!C3 -> Andrews, A.
B44: 3 | C44: ='Shelf 2 - Small Books'!B4 -> Asexuality: A Brief Introduction | D44: ='Shelf 2 - Small Books'!C4
B45: =B44+1 -> 4 | C45: ='Shelf 2 - Small Books'!B5 -> Gay American History | D45: ='Shelf 2 - Small Books'!C5 -> Katz, Johnathan
B46: =B45+1 -> 5 | C46: ='Shelf 2 - Small Books'!B6 -> Rust Belt Femme | D46: ='Shelf 2 - Small Books'!C6 -> Jolie, Rachael Anne
B47: =B46+1 -> 6 | C47: ='Shelf 2 - Small Books'!B7 -> The Queens' English | D47: ='Shelf 2 - Small Books'!C7 -> Davis, Chloe O.
B48: =B47+1 -> 7 | C48: ='Shelf 2 - Small Books'!B8 -> The Winning Life: An Indroduction to Buddhist Practice | D48: ='Shelf 2 - Small Books'!C8
B49: =B48+1 -> 8 | C49: ='Shelf 2 - Small Books'!B9 | D49: ='Shelf 2 - Small Books'!C9
B50: =B49+1 -> 9 | C50: ='Shelf 2 - Small Books'!B10 | D50: ='Shelf 2 - Small Books'!C10
B51: =B50+1 -> 10 | C51: ='Shelf 2 - Small Books'!B11 | D51: ='Shelf 2 - Small Books'!C11
B52: =B51+1 -> 11 | C52: ='Shelf 2 - Small Books'!B12 | D52: ='Shelf 2 - Small Books'!C12
B53: =B52+1 -> 12 | C53: ='Shelf 2 - Small Books'!B13 | D53: ='Shelf 2 - Small Books'!C13
B54: =B53+1 -> 13 | C54: ='Shelf 2 - Small Books'!B14 | D54: ='Shelf 2 - Small Books'!C14
B55: =B54+1 -> 14 | C55: ='Shelf 2 - Small Books'!B15 | D55: ='Shelf 2 - Small Books'!C15
B56: =B55+1 -> 15 | C56: ='Shelf 2 - Small Books'!B16 | D56: ='Shelf 2 - Small Books'!C16
A57: THIRD SHELF - REGULAR BOOKS (A-J) | B57: 1 | C57: ='Shelf 3 - Regular Books (A-J)'!B2 -> Another Appalachia | D57: ='Shelf 3 - Regular Books (A-J)'!C2 -> Avashia, Neema
B58: =B57+1 -> 2 | C58: ='Shelf 3 - Regular Books (A-J)'!B3 -> Fun Home copy 1 | D58: ='Shelf 3 - Regular Books (A-J)'!C3 -> Bechdel, Alison
...

Sheet Shelf 1 - DVDs
A1: # on Shelf | B1: DVD Title | C1: Author Name
A2: 1 | B2: A Single Man
A3: =A2+1 -> 2 | B3: Becoming Chaz
A4: =A3+1 -> 3 | B4: black./womyn: conversations with lesbians of African descent.
A5: =A4+1 -> 4 | B5: Bridegroom
A6: =A5+1 -> 5 | B6: Chely Wright: Wish Me Away
A7: =A6+1 -> 6 | B7: Circumstance
A8: =A7+1 -> 7 | B8: Everybody's Fine
A9: =A8+1 -> 8 | B9: for the Bible tells me so
A10: =A9+1 -> 9 | B10: happy
A11: =A10+1 -> 10 | B11: Happy Together
A12: =A11+1 -> 11 | B12: Heartbeats
A13: =A12+1 -> 12 | B13: Heavenly Creatures
A14: =A13+1 -> 13 | B14: high art
... A37: =A36+1 -> 36 | B37: Y Tu Mama Tambien
A38: =A37+1 -> 37
A39: =A38+1 -> 38
A40: =A39+1 -> 39
A41: =A40+1 -> 40
A42: =A41+1 -> 41
A43: =A42+1 -> 42
A44: =A43+1 -> 43
A45: =A44+1 -> 44
A46: =A45+1 -> 45
A47: =A46+1 -> 46
A48: =A47+1 -> 47
A49: =A48+1 -> 48
... A101: =A100+1 -> 100

Sheet Shelf 2 - Small Books
A1: # on Shelf | B1: Book Title | C1: Author Name
A2: 1 | B2: A Quick & Easy Guide to Consent | C2: Rotman, Isabella & Howard, Luke B.
A3: =A2+1 -> 2 | B3: A Quick & Easy Guide to Sex & Disability | C3: Andrews, A.
A4: =A3+1 -> 3 | B4: Asexuality: A Brief Introduction
A5: =A4+1 -> 4 | B5: Gay American History | C5: Katz, Johnathan
A6: =A5+1 -> 5 | B6: Rust Belt Femme | C6: Jolie, Rachael Anne
A7: =A6+1 -> 6 | B7: The Queens' English | C7: Davis, Chloe O.
A8: =A7+1 -> 7 | B8: The Winning Life: An Indroduction to Buddhist Practice
A9: =A8+1 -> 8
A10: =A9+1 -> 9
A11: =A10+1 -> 10
A12: =A11+1 -> 11
A13: =A12+1 -> 12
A14: =A13+1 -> 13
A15: =A14+1 -> 14
A16: =A15+1 -> 15
A17: =A16+1 -> 16
A18: =A17+1 -> 17
A19: =A18+1 -> 18
A20: =A19+1 -> 19
... A101: =A100+1 -> 100

Sheet Shelf 3 - Regular Books (A-J)
A1: # on Shelf | B1: Book Title | C1: Author Name
A2: 1 | B2: Another Appalachia | C2: Avashia, Neema
A3: =A2+1 -> 2 | B3: Fun Home copy 1 | C3: Bechdel, Alison
A4: =A3+1 -> 3 | B4: Fun Home copy 2 | C4: Bechdel, Alison
A5: =A4+1 -> 4 | B5: Are You My Mother? | C5: Bechdel, Alison
A6: =A5+1 -> 5 | B6: Understanding Asexuality | C6: Bogaert, Anthony F.
A7: =A6+1 -> 6 | B7: Gender Outlaw | C7: Bornstein, Kate
A8: =A7+1 -> 7 | B8: Dangerous Liaisons | C8: Brandt, Eric
A9: =A8+1 -> 8 | B9: "You Can Tell Just By Looking" | C9: Bronski, Michael; Pellegrini, Ann; Amico, Michael
A10: =A9+1 -> 9 | B10: Punch Me Up to the Gods | C10: Broome, Brian
A11: =A10+1 -> 10 | B11: Dry. | C11: Burroughs, Augusten
A12: =A11+1 -> 11 | B12: Running with Scissors | C12: Burroughs, Augusten
A13: =A12+1 -> 12 | B13: Private Lives, Public Conflicts | C13: Button, James A; Rienzo, Barbara A; Wald, Kenneth D.
A14: =A13+1 -> 13 | B14: The Night is Young | C14: Carrillo, Héctor
... A34: =A33+1 -> 33 | B34: Bi Any Other Name: Bisexual People Speak Out | C34: Hutchins, Loraine & Kaahumanu, Lani
A35: 34 | B35: A Brief History of Seven Killings | C35: James, Marton
A36: 35 | B36: The Fifth Season | C36: Jemison, N. K.
A37: 36 | B37: I Am Divine, So Are You | C37: Johnson, Jerry

Sheet Shelf 4 - Regular Books (K-W)
A1: # on Shelf | B1: Book Title | C1: Author Name
A2: 1 | B2: Gender Queer | C2: Kobabe, Maia
A3: =A2+1 -> 2 | B3: Female-to-Male Transsexualism | C3: Lothstein, Leslie Martin
A4: =A3+1 -> 3 | B4: Y'all Means All | C4: McNeill, Z. Zane
A5: =A4+1 -> 4 | B5: How Sex Changed | C5: Meyerowitz, Joanne
A6: =A5+1 -> 5 | B6: Designer Relationships | C6: Michaels, Mark A. & Johnson, Patricia
A7: =A6+1 -> 6 | B7: Out in the World | C7: Miller, Neil
A8: =A7+1 -> 7 | B8: Confessions of a Mask | C8: Mishima, Yukio
A9: =A8+1 -> 8 | B9: Gideon the Ninth | C9: Muir, Tamsyn
A10: =A9+1 -> 9 | B10: Harrow the Ninth | C10: Muir, Tamsyn
A11: =A10+1 -> 10 | B11: Nona the Ninth | C11: Muir, Tamsyn
A12: =A11+1 -> 11 | B12: Zoobiquity: The Astonishing Connection Between Human and Animal Health | C12: Natterson-Horowitz, Barbara
A13: =A12+1 -> 12 | B13: Love's Not Color Blind | C13: Patterson, Kavin A.
A14: =A13+1 -> 13 | B14: Detransition, Baby | C14: Peters, Torrey
... A35: =A34+1 -> 34 | B35: The Advocate College Guide for LGBT Students | C35: Windmeyer, Shane L.
A36: =A35+1 -> 35
A37: =A36+1 -> 36
A38: =A37+1 -> 37
A39: =A38+1 -> 38
A40: =A39+1 -> 39
A41: =A40+1 -> 40
A42: =A41+1 -> 41
A43: =A42+1 -> 42
A44: =A43+1 -> 43
A45: =A44+1 -> 44
A46: =A45+1 -> 45
A47: =A46+1 -> 46
... A106: =A105+1 -> 105

Sheet Shelf 5 - Oversized Books + Per
A1: # on Shelf | B1: Book Title | C1: Author Name
A2: 1 | B2: She's Not There | C2: Boylan, Jennifer Finney
A3: =A2+1 -> 2 | B3: David Bowie Made Me Gay: 100 Years of LGBT Music | C3: Bullock, Darryl W.
A4: =A3+1 -> 3 | B4: The Straight State | C4: Canaday, Margot
A5: =A4+1 -> 4 | B5: FTM: Female-to-Male Transsexuals in Society | C5: Devor, Holly
A6: =A5+1 -> 5 | B6: Passions Between Women | C6: Donoghue, Emma
A7: =A6+1 -> 6 | B7: Queer America | C7: Eaklor, Vicki L.
A8: =A7+1 -> 7 | B8: Trans Bodies, Trans Selves | C8: Erickson-Schroth, Laura
A9: =A8+1 -> 8 | B9: The Art of Drag | C9: Hall, Jake
A10: =A9+1 -> 9 | B10: brain Gender | C10: Hines, Melissa
A11: =A10+1 -> 10 | B11: Completely Queer | C11: Hogan, Steve & Hudson, Lee
A12: =A11+1 -> 11 | B12: Queer Love in Color | C12: Jordan, Jamal
A13: =A12+1 -> 12 | B13: Love Makes a Family | C13: Kaeser, Gigi & Gillespie, Peggy
A14: =A13+1 -> 13 | B14: Sexuality and Homosexuality | C14: Karlen, Arno
... A20: =A19+1 -> 19 | B20: When I Knew | C20: Trachtenberg, Robert
A21: =A20+1 -> 20
A22: =A21+1 -> 21
A23: =A22+1 -> 22
A24: =A23+1 -> 23
A25: =A24+1 -> 24
A26: =A25+1 -> 25
A27: =A26+1 -> 26
A28: =A27+1 -> 27
A29: =A28+1 -> 28
A30: =A29+1 -> 29
A31: =A30+1 -> 30
A32: =A31+1 -> 31
... A102: =A101+1 -> 101

Sheet Checkout Form Responses
A1: Timestamp | B1: What is your first name (name in use)? | C1: What is your last name? | D1: What is your network ID (abc123)? | E1: What is your email? | F1: Type down the full title AND author name (if applicable) of the item you are borrowing. | G1: What is today's date? This will be your "checkout date". | H1: Return Date | I1: Return date: By checking this box, I understand that I must return my item to an LGBT Center staff member no later than 4:30pm, two weeks from the checkout date (in the previous question). | J1: Renewal policy: I also understand that I may be able to renew this item, at the staff member's discretion. If I wish to renew this item, I will fill out this form again. | K1: Email Address | L1: Select the shelf that the item is located in. | M1: I am using this form to... (Note: You cannot use this form to hold a book. To check out a book for the first time, you must be present in the Center.) | N1: Type down the full title AND author name (if applicable) of the item you are returning. | O1: Select the shelf that the item is located in. | P1: What is today's date? This will be your "check-in date". | Q1: Select the staff member who confirmed your check-in status.
A2: 44832.52 | F2: Gideon the Ninth, Tamsyn Muir | G2: 44832 | H2: =G2+14 -> 44846 | I2: Yes, I understand. | J2: Yes, I understand. | K2: pht13@case.edu
A3: 44840.537 | F3: Harrow the Ninth, Tamsyn Muir | G3: 44840 | I3: Yes, I understand. | J3: Yes, I understand. | K3: pht13@case.edu
A4: 44855.867 | F4: Harrow the Ninth, Tamsyn Muir | G4: 37550 | I4: Yes, I understand. | J4: Yes, I understand. | K4: pht13@case.edu
A5: 44869.676 | F5: Harrow the Ninth | G5: 44869 | I5: Yes, I understand. | J5: Yes, I understand. | K5: pht13@case.edu
A6: 44872.519 | F6: Nona the Ninth, Tamsyn Muir | G6: 44872 | I6: Yes, I understand. | J6: Yes, I understand. | K6: pht13@case.edu
A7: 44874.541 | F7: Gender Outlaw - Kate Bornstien | G7: 44873 | I7: Yes, I understand. | J7: Yes, I understand. | K7: mar273@case.edu
A8: 44886.61 | F8: Nona the Ninth | G8: 44886 | I8: Yes, I understand. | J8: Yes, I understand. | K8: pht13@case.edu
A9: 44886.663 | F9: This is How You Lose the Time War by Amal El-Mohtar and Max Gladstone | G9: 44886 | I9: Yes, I understand. | J9: Yes, I understand. | K9: kdn29@case.edu
A10: 44887.475 | F10: Masculinities - RW Connell | G10: 44887 | I10: Yes, I understand. | J10: Yes, I understand. | K10: mar273@case.edu
A11: 44899.569 | F11: This is How You Lose the Time War by Amal El-Mohtar and Max Gladstone (renewel) | G11: 44899 | I11: Yes, I understand. | J11: Yes, I understand. | K11: kdn29@case.edu | L11: Third Shelf - Regular Books (A-J)
A12: 44900.703 | F12: Nona the Ninth by Tamsyn Muir | G12: 44900 | I12: Yes, I understand. | J12: Yes, I understand. | K12: pht13@case.edu | L12: Fourth Shelf - Regular Books (K-W) | M12: renew a book
A13: 44900.799 | F13: Masculinities - CW Connell | G13: 44900 | I13: Yes, I understand. | J13: Yes, I understand. | K13: mar273@case.edu | L13: Third Shelf - Regular Books (A-J) | M13: renew a book
A14: 44904.647 | K14: yxg590@case.edu | M14: check in a book | N14: This is how you lose the time war | O14: Third Shelf - Regular Books (A-J) | P14: 44904
A15: 44910.393 | K15: pht13@case.edu | M15: check in a book | N15: Nona the Ninth | O15: Fourth Shelf - Regular Books (K-W) | P15: 44910
A16: 44914.576 | K16: mar273@case.edu | M16: check in a book | N16: Masculinities - R W Connell | O16: Third Shelf - Regular Books (A-J) | P16: 44914
A17: 44957.667 | F17: Nona the Ninth (Tamsyn Muir) | G17: 44957 | I17: Yes, I understand. | J17: Yes, I understand. | K17: spm91@case.edu | L17: Fourth Shelf - Regular Books (K-W) | M17: check out a book (new check-out)
A18: 44964.656 | K18: spm91@case.edu | M18: check in a book | N18: Nona the Ninth - Tamsyn Muir | O18: Fourth Shelf - Regular Books (K-W) | P18: 44964
A19: 44966.752 | F19: Detransition Baby - Torrey peters; FTM — holly devor | G19: 44966 | I19: Yes, I understand. | J19: Yes, I understand. | K19: mar273@case.edu | L19: Third Shelf - Regular Books (A-J) | M19: check out a book (new check-out)
A20: 44966.754 | F20: Stone Butch Blues by Leslie Feinberg | G20: 44966 | I20: Yes, I understand. | J20: Yes, I understand. | K20: jrr216@case.edu | L20: Third Shelf - Regular Books (A-J) | M20: check out a book (new check-out)
A21: 44977.719 | F21: Happy Together | G21: 44977 | I21: Yes, I understand. | J21: Yes, I understand. | K21: act80@case.edu | L21: First Shelf - DVDs | M21: check out a book (new check-out)
A22: 44980.526 | K22: jrr216@case.edu | M22: check in an item | N22: Stone Butch Blues by Leslie Feinberg | O22: Third Shelf - Regular Books (A-J) | P22: 44980
A23: 44985.699 | K23: spm91@case.edu | M23: check in an item | N23: FTM: Female-To-Male Transsexuals in Society (Holly Devor) and Detransition, Baby (Torrey Peters) | O23: Third Shelf - Regular Books (A-J) | P23: 44985
A24: 45009.712 | F24: Girl Sex 101 - Allison Moon | G24: 45009 | I24: Yes, I understand. | J24: Yes, I understand. | K24: nem59@case.edu | L24: Fifth Shelf - Oversized Books + Periodicals | M24: check out an item (new check-out)
A25: 45012.628 | K25: nem59@case.edu | M25: check in an item | N25: Girl Sex 101 - Allison Moon | O25: Fifth Shelf - Oversized Books + Periodicals | P25: 45012
A26: 45184.693 | F26: Ace, what asexuality reveals about desire society and the meaning of sex, Angela Chen | G26: 45183 | I26: Yes, I understand. | J26: Yes, I understand. | K26: aeo48@case.edu | L26: Third Shelf - Regular Books (A-J) | M26: check out an item (new check-out)
A27: 45184.694 | F27: Gideon the ninth by tamsyn Muir | G27: 45184 | I27: Yes, I understand. | J27: Yes, I understand. | K27: mpd65@case.edu | L27: Fourth Shelf - Regular Books (K-W) | M27: check out an item (new check-out)
A28: 45187.528 | F28: This Is How You Lose the Time War by Max Gladstone | G28: 45187 | I28: Yes, I understand. | J28: Yes, I understand. | L28: Third Shelf - Regular Books (A-J) | M28: check out an item (new check-out)
A29: 45190.732 | F29: This is how you lose the time war - Amal El-Mohtar | I29: Yes, I understand. | J29: Yes, I understand. | L29: Third Shelf - Regular Books (A-J) | M29: check out an item (new check-out)
A30: 45191.598 | F30: Confessions of a mask by Yukio Mishima | G30: 45191 | I30: Yes, I understand. | J30: Yes, I understand. | L30: Fourth Shelf - Regular Books (K-W) | M30: check out an item (new check-out)
A31: 45196.758 | F31: Girl Sex 101 Allison Moon | G31: 45196 | I31: Yes, I understand. | J31: Yes, I understand. | L31: Fifth Shelf - Oversized Books + Periodicals | M31: check out an item (new check-out)
A32: 45203.588 | F32: Harrow the Ninth, Tamsyn Muir | G32: 45203 | I32: Yes, I understand. | J32: Yes, I understand. | L32: Fourth Shelf - Regular Books (K-W) | M32: check out an item (new check-out)
A33: 45205.683 | F33: Confessions of a mask by Yukio Mishima | G33: 45205 | I33: Yes, I understand. | J33: Yes, I understand. | L33: Fourth Shelf - Regular Books (K-W) | M33: renew an item
A34: 45215.562 | M34: check in an item | N34: Harrow the Ninth, Tamsyn Mur | O34: Fourth Shelf - Regular Books (K-W) | P34: 45215
A35: 45216.665 | M35: check in an item | N35: Gideon the Ninth by Tasmyn Muir | O35: Fourth Shelf - Regular Books (K-W) | P35: 45216
A36: 45216.665 | M36: check in an item | N36: Harrow the Ninth by Tasmyn Muir | O36: Fourth Shelf - Regular Books (K-W) | P36: 45216
A37: 45216.666 | M37: check in an item | N37: Girl Sex 101 by Allison Moon and KD Diamond | O37: Fifth Shelf - Oversized Books + Periodicals | P37: 45216
A38: 45219.711 | F38: When the angels left the old country by Sacha lamb | G38: 45219 | I38: Yes, I understand. | J38: Yes, I understand. | L38: Fourth Shelf - Regular Books (K-W) | M38: check out an item (new check-out)
A39: 45233.685 | F39: Gideon the Ninth | G39: 45233 | I39: Yes, I understand. | J39: Yes, I understand. | L39: Fourth Shelf - Regular Books (K-W) | M39: check out an item (new check-out)
A40: 45247.344 | F40: Ore | G40: 45248 | I40: Yes, I understand. | J40: Yes, I understand. | L40: Fourth Shelf - Regular Books (K-W) | M40: check out an item (new check-out)
...

Sheet Main Catalog
A1: Title | B1: Author | C1: Status | D1: Checked Out To | E1: Checked Out On | G1: Status | H1: Is it on the shelf?
A2: "You Can Tell Just By Looking" | B2: Bronski, Michael; Pellegrini, Ann; Amico, Michael | H2: y
A3: A Brief History of Seven Killings (signed) | B3: James, Marlon | H3: y
A4: A Home at the End of the World | B4: Cunningham, Michael | H4: y
A5: Are You My Mother? A Comic Drama (signed) | B5: Bechdel, Alison | H5: y
A6: As Nature Made Him | B6: Colapinto, John | H6: y
A7: Beyond Survival | B7: Dixon, Ejeris & Piepzna-Samarasinha, Leah Lakshmi | H7: y
A8: Best Little Boy in the World (2 Copies) | B8: Tobias, Andrew | H8: y
A9: Bi Any Other Name | B9: Hutchins, Loraine and Ka'ahumanu, Lani | H9: y
A10: Black Queer Studies | B10: Johnson, Patrick | H10: y
A11: Brain Gender | B11: Hines, Melissa | H11: y
A12: Changing Sex | B12: Hausman, Bernice | H12: y
A13: Completely Queer | B13: Hogan and Hudson | H13: y
... A23: Fun Home | B23: Bechdel, Alison | H23: y (2)
A24: Fun Home: A Family Tragicomic (signed) | B24: Bechdel, Alison | G24: Checked out 8/22/18 (cxn168)
A25: Gay American History | B25: Katz, Jonathan | H25: y
A26: Gay Shame | B26: Halperin, David | G26: Checked out 9/22/17 (AmariYah has the sticky note for the person that checked it out) | H26: (AmariYah has the sticky note for the person that checked it out)
A27: Gender Outlaw | B27: Bornstein, Kate | H27: y
A28: Gender Reversals and Gender Cultures | B28: Ramet, Sabrina Petra | H28: y
A29: Gender Trouble | B29: Butler, Judith
A30: Gideon the Ninth | B30: Muir, Tamsyn | H30: y
A31: Girl Sex 101 | B31: Moon, Allison & Diamond, KD | H31: y
A32: Global Homophobia | B32: Weiss and Bosia | H32: y
A33: How Sex Changed | B33: Meyerowitz | H33: y
A34: I Am Divine: So Are You | B34: Pattanaik, Devdutt | G34: checked out 9/5/18 | H34: gxs372
A35: Just Girls | B35: Gold, Rachel | H35: y
A36: Lesbian Culture: An Anthology | B36: Penelope, Julia, and Wolfe, Susan | H36: y
A37: LGBTQ Cleveland | B37: Schneck, Ken | G37: Returned 1/28 | H37: in returned
A38: Love Makes a Family | B38: Gillespie, Peggy; Kaeser, Gigi | H38: y
A39: Love's Not Color Blind | B39: Patterson, Kevin
A40: Masculinities | B40: Connell | H40: y
A41: Myths of Gender | B41: Fausto-Sterling, Anne | H41: y
A42: Naked | B42: Sedaris, David | H42: y
A43: Odd Girls and Twilight Lovers | B43: Faderman, Lillian | H43: y
A44: Out in the World | B44: Miller, Neil | H44: y
A45: Out of Bounds | B45: Simmons, Roy | H45: y
A46: Overcoming the Pain of Growing UP Gay in a Straight Man's World | B46: Downs, Alan
A47: Passions Between Women | B47: Donoghue, Emma | H47: y
A48: Private Lives, Public Conflicts | B48: Button, James
A49: Queer America | B49: Eaklor, Vicki | H49: y
...
